<?xml version="1.0"?>
<robot xmlns:xacro="http://ros.org/wiki/xacro" name="former">

  <xacro:include filename="$(find former_description)/urdf/include/tim571.urdf.xacro" />
  <xacro:include filename="$(find former_description)/urdf/include/d435.urdf.xacro" />

  <xacro:property name="PI" value="3.1415926535897931" />

  <xacro:property name="base_width" value="0.41" />
  <xacro:property name="base_length" value="0.41" />
  <xacro:property name="base_height" value="1.11" />
  <xacro:property name="wheel_radius" value="0.085" />
  <xacro:property name="wheel_width" value="0.06" />

  <xacro:macro name="box_inertia" params="m w h d">
    <inertial>
      <origin xyz="0 0 0" rpy="0 0 0" />
      <mass value="${m}" />
      <inertia ixx="${(m/12) * (h*h + d*d)}" ixy="0.0" ixz="0.0" iyy="${(m/12) * (w*w + d*d)}" iyz="0.0" izz="${(m/12) * (w*w + h*h)}" />
    </inertial>
  </xacro:macro>

  <xacro:macro name="cylinder_inertia" params="m r h">
    <inertial>
      <origin xyz="0 0 0" rpy="0 0 0" />
      <mass value="${m}" />
      <inertia ixx="${(m/12) * (3*r*r + h*h)}" ixy="0" ixz="0" iyy="${(m/12) * (3*r*r + h*h)}" iyz="0" izz="${(m/2) * (r*r)}" />
    </inertial>
  </xacro:macro>

  <material name="black">
    <color rgba="0.15 0.15 0.15 1.0" />
  </material>

  <link name="base_link">
    <visual>
      <origin xyz="0 0 0" rpy="0 0 0" />
      <geometry>
        <mesh filename="file://$(find former_description)/meshes/former.dae" />
      </geometry>
    </visual>
    <collision>
      <origin xyz="0 0 0" rpy="0 0 0" />
      <geometry>
        <mesh filename="file://$(find former_description)/meshes/former.dae" />
      </geometry>
    </collision>
    <xacro:box_inertia m="30.0" w="${base_width}" d="${base_length}" h="${base_height}" />
  </link>

  <joint name="left_wheel_joint" type="continuous">
    <parent link="base_link" />
    <child link="left_wheel_link" />
    <origin xyz="0 0.15 0.0016" rpy="0 0 0" />
    <axis xyz="0 1 0" rpy="0 0 0" />
  </joint>

  <link name="left_wheel_link">
    <visual>
      <origin xyz="0 -0.0234 0" rpy="0 0 0" />
      <geometry>
        <mesh filename="file://$(find former_description)/meshes/wheel.stl" scale="0.001 0.001 0.001" />
      </geometry>
      <material name="black" />
    </visual>
    <collision>
      <origin xyz="0 -0.0234 0" rpy="0 0 0" />
      <geometry>
        <mesh filename="file://$(find former_description)/meshes/wheel.stl" scale="0.001 0.001 0.001" />
      </geometry>
    </collision>
    <xacro:cylinder_inertia m="3.0" r="${wheel_radius}" h="${wheel_width}" />
  </link>

  <joint name="right_wheel_joint" type="continuous">
    <parent link="base_link" />
    <child link="right_wheel_link" />
    <origin xyz="0 -0.15 0.0016" rpy="0 0 0" />
    <axis xyz="0 1 0" rpy="0 0 0" />
  </joint>

  <link name="right_wheel_link">
    <visual>
      <origin xyz="0 0.0234 0" rpy="0 0 3.1415926535897931" />
      <geometry>
        <mesh filename="file://$(find former_description)/meshes/wheel.stl" scale="0.001 0.001 0.001" />
      </geometry>
      <material name="black" />
    </visual>
    <collision>
      <origin xyz="0 0.0234 0" rpy="0 0 3.1415926535897931" />
      <geometry>
        <mesh filename="file://$(find former_description)/meshes/wheel.stl" scale="0.001 0.001 0.001" />
      </geometry>
    </collision>
    <xacro:cylinder_inertia m="3.0" r="${wheel_radius}" h="${wheel_width}" />
  </link>

  <joint name="imu_joint" type="fixed">
    <parent link="base_link" />
    <child link="imu_link" />
    <origin xyz="0.134 0 0.067" rpy="0 0 0" />
  </joint>

  <link name="imu_link">
    <visual>
      <geometry>
        <box size="0.03 0.03 0.01" />
      </geometry>
    </visual>
    <collision>
      <geometry>
        <box size="0.03 0.03 0.01" />
      </geometry>
    </collision>
    <xacro:box_inertia m="0.1" w="0.03" d="0.03" h="0.01" />
  </link>

  <xacro:sensor_tim571 parent="base_link" min_angle="-1.74533" max_angle="1.74533" gazebo="true">
    <origin xyz="0.1592 0 0.2285" rpy="${PI} 0 0" />
  </xacro:sensor_tim571>

  <!--xacro:sensor_d435 parent="base_link" name="camera">
    <origin xyz="0.178 0 0.0686" rpy="0 -${PI/12} 0" />
  </xacro:sensor_d435-->

  <!--link name="top_structure">
    <visual>
      <origin xyz="0 0 0" rpy="0 0 -${PI/2}"/>
      <geometry>
        <mesh filename="package://former_description/meshes/top_structure_roas.STL"/>
      </geometry>
      <material name="grey">
        <color rgba="0.2 0.2 0.2 1"/>
      </material>
    </visual>
    <collision>
      <origin xyz="0 0 0" rpy="0 0 -${PI/2}"/>
      <geometry>
        <mesh filename="package://former_description/meshes/top_structure_roas.STL"/>
      </geometry>
    </collision>
    <xacro:box_inertia m="5.0" w="${base_width}" d="${base_length}" h="0.5" />
  </link-->

  <!--joint name="top_structure_joint" type="fixed">
    <parent link="base_link"/>
    <child link="top_structure"/>
    <origin xyz="0 0 0.29" rpy="0 0 0"/>
  </joint-->

  <!-- <link name="matterport_link" />

  <joint name="matterport_joint" type="fixed">
    <parent link="top_structure" />
    <child link="matterport_link" />
    <origin xyz="0 0 0.45" rpy="0 0 0" />
  </joint> -->

  <gazebo>
    <plugin name="gazebo_ros_control" filename="libgazebo_ros_control.so">
      <robotNamespace>/</robotNamespace>
    </plugin>
  </gazebo>

  <gazebo reference="base_link">
    <mu1>0.01</mu1>
    <mu2>0.01</mu2>
    <turnGravityOff>false</turnGravityOff>
  </gazebo>

  <gazebo reference="left_wheel_link">
    <material>Gazebo/DarkGrey</material>
  </gazebo>

  <gazebo reference="right_wheel_link">
    <material>Gazebo/DarkGrey</material>
  </gazebo>

  <transmission name="left_wheel_trans">
    <type>transmission_interface/SimpleTransmission</type>
    <joint name="left_wheel_joint">
      <hardwareInterface>hardware_interface/VelocityJointInterface</hardwareInterface>
    </joint>
    <actuator name="left_actuator">
      <mechanicalReduction>1</mechanicalReduction>
    </actuator>
  </transmission>

  <transmission name="right_wheel_trans">
    <type>transmission_interface/SimpleTransmission</type>
    <joint name="right_wheel_joint">
      <hardwareInterface>hardware_interface/VelocityJointInterface</hardwareInterface>
    </joint>
    <actuator name="right_actuator">
      <mechanicalReduction>1</mechanicalReduction>
    </actuator>
  </transmission>

  <gazebo reference="imu_link">
    <gravity>true</gravity>
    <sensor name="imu_sensor" type="imu">
      <always_on>true</always_on>
      <update_rate>100</update_rate>
      <visualize>false</visualize>
      <topic>__default_topic__</topic>
      <plugin filename="libgazebo_ros_imu_sensor.so" name="imu_plugin">
        <topicName>imu</topicName>
        <bodyName>imu_link</bodyName>
        <updateRateHZ>10.0</updateRateHZ>
        <gaussianNoise>0.0</gaussianNoise>
        <xyzOffset>0 0 0</xyzOffset>
        <rpyOffset>0 0 0</rpyOffset>
        <frameName>imu_link</frameName>
      </plugin>
      <pose>0 0 0 0 0 0</pose>
    </sensor>
  </gazebo>
  <gazebo>
    <plugin name="former_controller" filename="libgazebo_ros_diff_drive.so">
      <commandTopic>cmd_vel</commandTopic>
      <odometryTopic>odom</odometryTopic>
      <odometryFrame>odom</odometryFrame>
      <odometrySource>world</odometrySource>
      <publishOdomTF>true</publishOdomTF>
      <robotBaseFrame>base_link</robotBaseFrame>
      <publishWheelTF>true</publishWheelTF>
      <publishTf>true</publishTf>
      <publishWheelJointState>true</publishWheelJointState>
      <updateRate>50</updateRate>
      <leftJoint>left_wheel_joint</leftJoint>
      <rightJoint>right_wheel_joint</rightJoint>
      <wheelSeparation>0.305</wheelSeparation>
      <wheelDiameter>0.17</wheelDiameter>
      <wheelAcceleration>1.0</wheelAcceleration>
      <wheelTorque>50</wheelTorque>
      <legacyMode>false</legacyMode>
      <rosDebugLevel>na</rosDebugLevel>
    </plugin>
  </gazebo>
</robot>
